<mujoco model="Interbotix">

    <compiler angle="radian" meshdir="../../../simhive/interbotix_sim" texturedir="../../../simhive/interbotix_sim"/>

    <size njmax='1000' nconmax='1000'/>

    <include file="../../../simhive/scene_sim/topfloor_scene.xml"/>
    <include file="../../../simhive/interbotix_sim/vx300/assets/assets.xml"/>
    <include file="../../../simhive/plus_sim/large_table/large_table_asset.xml"/>

    <include file="../../../simhive/YCB_sim/includes/defaults_ycb.xml"/>
    <include file="../../../simhive/YCB_sim/includes/assets_004_sugar_box.xml"/>
    <include file="../../../simhive/YCB_sim/includes/assets_003_cracker_box.xml"/>


    <worldbody>

        <camera name='left_cam' pos='-1.2 -0.5 1.8' quat='0.78 0.49 -0.22 -0.32'/>
        <camera name='right_cam' pos='1.2 -0.5 1.8' quat='0.76 0.5 0.21 0.35'/>
        <camera name='top_cam' pos='0 0.5 2.2' euler='0 0 0'/>
        <site name='workspace' type='box' size='.6 .375 .25' pos='0 0.475 1.0' group='3' rgba='0 0 .4 .2'/>

        <!-- Robot -->
        <body pos='-0.5 0 .76' euler='0 0 0'>
            <include file="../../../simhive/interbotix_sim/vx300/assets/arm0.xml"/>
        </body>

        <body pos='0.5 0 0.76' euler='0 0 3.1415'>
            <include file="../../../simhive/interbotix_sim/vx300/assets/arm1.xml"/>
        </body>

        <!-- simple Table -->
        <body pos='0 0 0'>
            <include file="../../../simhive/plus_sim/large_table/large_table_body.xml"/>
        </body>

        <!-- tasks details added here via include-->
        <site name='target' type='cylinder' size='.088 0.021' pos='0.4 0.5 0.78' group='1' rgba='.1 .8 .2 .4'/>

        <!-- object -->
        <body pos="0.0 0.5 .8">
            <include file="../../../simhive/YCB_sim/includes/body_004_sugar_box.xml"/>
            <site name="sugarbox" size="0.01" pos="0 0 .088"/>
            <joint name="Tx" axis="1 0 0" type="slide" damping="0" limited="true" range="-1.0 1.0"/>
            <joint name="Ty" axis="0 1 0" type="slide" damping="0" limited="true" range="-0.5 0.5"/>
            <joint name="Tz" axis="0 0 1" type="slide" damping="0" limited="true" range="-1.0 1.0"/>
            <joint name="Rx" axis="1 0 0" type="hinge" damping="0" limited="true" range="-3.14 3.14"/>
            <joint name="Ry" axis="0 1 0" type="hinge" damping="0" limited="true" range="-3.14 3.14"/>
            <joint name="Rz" axis="0 0 1" type="hinge" damping="0" limited="true" range="-3.14 3.14"/>
        </body>

    </worldbody>

    <sensor>
        <jointpos name="Tx" joint="Tx"/>
        <jointpos name="Ty" joint="Ty"/>
        <jointpos name="Tz" joint="Tz"/>
        <jointpos name="Rx" joint="Rx"/>
        <jointpos name="Ry" joint="Ry"/>
        <jointpos name="Rz" joint="Rz"/>
    </sensor>

</mujoco>