<mujocoinclude>
    <body name="base" quat="1 0 0 1" childclass="ur5e">
        <inertial mass="4.0" pos="0 0 0" diaginertia="0.00443333156 0.00443333156 0.0072" />
        <geom mesh="base_0" material="black" class="visual" />
        <geom mesh="base_1" material="jointgray" class="visual" />
        <body name="shoulder_link" pos="0 0 0.163">
            <inertial mass="3.7" pos="0 0 0" diaginertia="0.0102675 0.0102675 0.00666" />
            <joint name="shoulder_pan_joint" class="size3" axis="0 0 1" />
            <geom mesh="shoulder_0" material="urblue" class="visual" />
            <geom mesh="shoulder_1" material="black" class="visual" />
            <geom mesh="shoulder_2" material="jointgray" class="visual" />
            <geom class="collision" size="0.06 0.06" pos="0 0 -0.04" />
            <body name="upper_arm_link" pos="0 0.138 0" quat="1 0 1 0">
                <inertial mass="8.393" pos="0 0 0.2125" diaginertia="0.133886 0.133886 0.0151074" />
                <joint name="shoulder_lift_joint" class="size3" />
                <geom mesh="upperarm_0" material="linkgray" class="visual" />
                <geom mesh="upperarm_1" material="black" class="visual" />
                <geom mesh="upperarm_2" material="jointgray" class="visual" />
                <geom mesh="upperarm_3" material="urblue" class="visual" />
                <geom class="collision" pos="0 -0.04 0" quat="1 1 0 0" size="0.06 0.06" />
                <geom class="collision" size="0.05 0.2" pos="0 0 0.2" />
                <body name="forearm_link" pos="0 -0.131 0.425">
                    <inertial mass="2.275" pos="0 0 0.196" diaginertia="0.0311796 0.0311796 0.004095" />
                    <joint name="elbow_joint" class="size3_limited" />
                    <geom mesh="forearm_0" material="urblue" class="visual" />
                    <geom mesh="forearm_1" material="linkgray" class="visual" />
                    <geom mesh="forearm_2" material="black" class="visual" />
                    <geom mesh="forearm_3" material="jointgray" class="visual" />
                    <geom class="collision" pos="0 0.08 0" quat="1 1 0 0" size="0.055 0.06" />
                    <geom class="collision" size="0.038 0.19" pos="0 0 0.2" />
                    <body name="wrist_1_link" pos="0 0 0.392" quat="1 0 1 0">
                        <inertial mass="1.219" pos="0 0.127 0" diaginertia="0.0025599 0.0025599 0.0021942" />
                        <joint name="wrist_1_joint" class="size1" />
                        <geom mesh="wrist1_0" material="black" class="visual" />
                        <geom mesh="wrist1_1" material="urblue" class="visual" />
                        <geom mesh="wrist1_2" material="jointgray" class="visual" />
                        <geom class="collision" pos="0 0.05 0" quat="1 1 0 0" size="0.04 0.07" />
                        <body name="wrist_2_link" pos="0 0.127 0">
                            <inertial mass="1.219" pos="0 0 0.1" diaginertia="0.0025599 0.0025599 0.0021942" />
                            <joint name="wrist_2_joint" axis="0 0 1" class="size1" />
                            <geom mesh="wrist2_0" material="black" class="visual" />
                            <geom mesh="wrist2_1" material="urblue" class="visual" />
                            <geom mesh="wrist2_2" material="jointgray" class="visual" />
                            <geom class="collision" size="0.04 0.06" pos="0 0 0.04" />
                            <geom class="collision" pos="0 0.02 0.1" quat="1 1 0 0" size="0.04 0.04" />
                            <body name="wrist_3_link" pos="0 0 0.1">
                                <inertial mass="0.1889" pos="0 0.0771683 0" quat="1 0 0 1" diaginertia="0.000132134 9.90863e-05 9.90863e-05" />
                                <joint name="wrist_3_joint" class="size1" />
                                <geom material="linkgray" mesh="wrist3" class="visual" />
                                <geom class="eef_collision" pos="0 0.08 0" quat="1 1 0 0" size="0.04 0.02" />
                                <!-- <site name="attachment_site" pos="0 0.1 0" quat="-1 1 0 0" /> -->
                                <site name='' pos='0 0 0' size='0.01' euler='0 0 0' rgba="1 0 0 0.25"/>
                                <body name="gripper_base" pos="0 0.1 0" quat="-1 1 0 0">
                                    <site name="mount" group="3" />
                                    <!-- <camera name='debug' pos="-0.135 -0.200 0.087"
                                        xyaxes="0.825 -0.565 0.000 0.071 0.104 0.992" />
                                    <camera name='debug2' pos="-0.002 -0.145 -0.170"
                                        xyaxes="1.000 -0.005 -0.000 -0.005 -0.884 0.467" /> -->
                        
                                    <!-- milibar -->
                                    <geom size="0.041 0.009" type="cylinder" material="milibar" class="gripper_visual"
                                        pos="0 0 0.009" />
                                    <geom size="0.041 0.009" type="cylinder" class="gripper_collision" pos="0 0 0.009" />
                        
                                    <geom type="mesh" mesh="mount" material="milibar_connector" class="gripper_visual"
                                        pos="0 0 0.008" euler="0 0 1.57079632679" />
                                    <geom type="mesh" mesh="mount_collider_1" class="gripper_collision" pos="0 0 0.008"
                                        euler="0 0 1.57079632679" />
                                    <geom type="mesh" mesh="mount_collider_2" class="gripper_collision" pos="0 0 0.008"
                                        euler="0 0 1.57079632679" />
                                    <site name="cam_mount" size="0.001" group="2"
                                        pos="-0.032507  -0.065 0.054202" />
                        
                                    <geom mesh="base" type="mesh" class="gripper_visual" mass="0.5" material="gripper"
                                        pos="0 0 0.03" />
                                    <geom size="0.073 0.025 0.036" type="box" class="gripper_collision" pos="0 0 0.066" />
                        
                                    <body name="right_finger" pos="0 0 0.102" euler="0 0 1.57079632679">
                                        <joint name="right_driver_joint" range="0.00 0.054" damping="20"
                                            type="slide" axis="0 -1 0" />
                                        <geom mesh="finger" type="mesh" class="gripper_visual" mass="0.1" material="finray_material" />
                                        <geom mesh="finger_collider" type="mesh" class="finray_collision" />
                                        <geom size="0.015 0.01 0.01" type="box" class="gripper_collision" pos="0 -0.012 0.0105" />
                                    </body>
                                    <body name="left_finger" pos="0 0 0.102" euler="0 0 -1.57079632679">
                                        <joint name="left_driver_joint" range="0.00 0.054" damping="20"
                                            type="slide" axis="0 -1 0" />
                                        <geom mesh="finger" type="mesh" class="gripper_visual" mass="0.1" material="finray_material" />
                                        <geom mesh="finger_collider" type="mesh" class="finray_collision" />
                                        <geom size="0.015 0.01 0.01" type="box" class="gripper_collision" pos="0 -0.012 0.0105" />
                                    </body>
                                    <site name="end_effector" group="3" pos="0 0 0.25491" />
                                </body>
                            </body>
                        </body>
                    </body>
                </body>
            </body>
        </body>
    </body>
</mujocoinclude>