<mujocoinclude>
    <body name="vx300_arm0_base_link" pos="0 0 0" childclass="interbotix">
        <geom quat="0.707107 0 0 0.707107" type="mesh" mesh="vx300_1_base" />
        <body name="vx300_arm0_shoulder_link" pos="0 0 0.082">
            <inertial pos="0.000259233 -3.3552e-06 0.0116129" quat="-0.476119 0.476083 0.52279 0.522826" mass="0.798614" diaginertia="0.00120156 0.00113744 0.0009388" />
            <joint name="vx300_arm0_waist" pos="0 0 0" axis="0 0 1" limited="true" range="-3.14158 3.14158" frictionloss="0.1" />
            <geom pos="0 0 -0.003" quat="0.707107 0 0 0.707107" type="mesh" mesh="vx300_2_shoulder" />
            <body name="vx300_arm0_upper_arm_link" pos="0 0 0.04805">
                <inertial pos="0.0206949 4e-10 0.226459" quat="0 0.0728458 0 0.997343" mass="0.792592" diaginertia="0.00911338 0.008925 0.000759317" />
                <joint name="vx300_arm0_shoulder" pos="0 0 0" axis="0 1 0" limited="true" range="-1.85005 1.25664" frictionloss="0.1" />
                <geom quat="0.707107 0 0 0.707107" type="mesh" mesh="vx300_3_upper_arm" />
                <body name="vx300_arm0_forearm_link" pos="0.05955 0 0.3">
                    <inertial pos="0.181265 -0.000206504 0" quat="0.000811359 0.707106 -0.000811359 0.707106" mass="0.544659" diaginertia="0.005574 0.00544703 0.000226673" />
                    <joint name="vx300_arm0_elbow" pos="0 0 0" axis="0 1 0" limited="true" range="-1.76278 1.6057" frictionloss="0.1" />
                    <geom quat="0.707107 0 0 0.707107" type="mesh" mesh="vx300_4_forearm" />
                    <body name="vx300_arm0_wrist_link" pos="0.3 0 0">
                        <inertial pos="0.046743 -7.6652e-06 0.010565" quat="-0.00100191 0.544586 0.0026583 0.8387" mass="0.115395" diaginertia="5.45707e-05 4.63101e-05 4.32692e-05" />
                        <joint name="vx300_arm0_wrist_angle" pos="0 0 0" axis="0 1 0" limited="true" range="-1.8675 2.23402" frictionloss="0.1" />
                        <geom quat="0.707107 0 0 0.707107" type="mesh" mesh="vx300_5_wrist" />
                        <body name="vx300_arm0_gripper_link" pos="0.069744 0 0">
                            <inertial pos="0.0395662 -2.56311e-07 0.00400649" quat="0.62033 0.619916 -0.339682 0.339869" mass="0.251652" diaginertia="0.000689546 0.000650316 0.000468142" />
                            <joint name="vx300_arm0_wrist_rotate" pos="0 0 0" axis="1 0 0" limited="true" range="-3.14158 3.14158" frictionloss="0.1" />
                            <geom pos="-0.02 0 0" quat="0.707107 0 0 0.707107" type="mesh" mesh="vx300_6_gripper" />
                            <geom pos="-0.020175 0 0" quat="0.707107 0 0 0.707107" type="mesh" mesh="vx300_8_gripper_bar" />
                            <body name="vx300_arm0_gripper_prop_link" pos="0.0485 0 0">
                                <inertial pos="0.002378 2.85e-08 0" quat="0 0 0.897698 0.440611" mass="0.008009" diaginertia="4.2979e-06 2.8868e-06 1.5314e-06" />
                                <joint name="vx300_arm0_gripper" pos="0 0 0" axis="1 0 0" frictionloss="0.1" />
                                <geom pos="-0.0685 0 0" quat="0.707107 0 0 0.707107" type="mesh" mesh="vx300_7_gripper_prop" />
                            </body>
                            <body name="vx300_arm0_right_finger_link" pos="0.0687 0 0">
                                <inertial pos="0.017344 0.0060692 0" quat="0.44937 -0.44937 0.545955 -0.545955" mass="0.034796" diaginertia="2.48002e-05 1.417e-05 1.20798e-05" />
                                <joint name="vx300_arm0_right_finger" pos="0 0 0" axis="0 1 0" type="slide" limited="true" range="-0.057 -0.021" frictionloss="0.1" />
                                <geom pos="-0.0404 0.0575 0" quat="0.5 0.5 0.5 0.5" type="mesh" mesh="vx300_9_gripper_finger" />
                            </body>
                            <body name="vx300_arm0_left_finger_link" pos="0.0687 0 0">
                                <inertial pos="0.017344 -0.0060692 0" quat="0.449364 0.449364 -0.54596 -0.54596" mass="0.034796" diaginertia="2.48003e-05 1.417e-05 1.20797e-05" />
                                <joint name="vx300_arm0_left_finger" pos="0 0 0" axis="0 1 0" type="slide" limited="true" range="0.021 0.057" frictionloss="0.1" />
                                <geom pos="-0.0404 -0.0575 0" quat="-0.5 0.5 -0.5 0.5" type="mesh" mesh="vx300_9_gripper_finger" />
                            </body>
                            <site name='vx300_arm0_end_effector' pos='0.1 0 0' size='0.01' euler='0 0 0' rgba="1 0 0 0.25"/>
                            <camera name='vx300_arm0_gripper_cam' pos='0 0 0.05' euler="1.57 -1.57 0" />
                        </body>
                    </body>
                </body>
            </body>
        </body>
    </body>
</mujocoinclude>
